Exception in thread Thread-2:
Traceback (most recent call last):
  File "/home/simanok/.local/lib/python3.6/site-packages/mysql/connector/connection_cext.py", line 472, in cmd_query
    raw_as_string=raw_as_string)
_mysql_connector.MySQLInterfaceError: Duplicate entry '2019-10-03 23:40:51-15384' for key 'PRIMARY'

During handling of the above exception, another exception occurred:

Traceback (most recent call last):
  File "/usr/lib/python3.6/threading.py", line 916, in _bootstrap_inner
    self.run()
  File "/usr/lib/python3.6/threading.py", line 864, in run
    self._target(*self._args, **self._kwargs)
  File "bot.py", line 70, in mainloop
    dbm.answer(managers_answers_wrapper.payload)
  File "/home/robots/crmbot/telegram/CommunicatorBot/db_manager.py", line 44, in answer
    c.execute(insert_sql, t)
  File "/home/simanok/.local/lib/python3.6/site-packages/mysql/connector/cursor_cext.py", line 266, in execute
    raw_as_string=self._raw_as_string)
  File "/home/simanok/.local/lib/python3.6/site-packages/mysql/connector/connection_cext.py", line 475, in cmd_query
    sqlstate=exc.sqlstate)
mysql.connector.errors.IntegrityError: 1062 (23000): Duplicate entry '2019-10-03 23:40:51-15384' for key 'PRIMARY'
